Workbook

Sheet Consumption Guide
A2: AGE | B2: STAND | C2: STAND | D2: STANDARD FEED CONSUMPTION
A3: DAYS | B3: COCKS | C3: PULLS | D3: MIXED SEX 4% MORT. | F3: WINTER | G3: COBB
D4: F.C.R. | E4: F.C.R. | F4: MIX | G4: 500
D5: =SUM(D8:D50)/1800/0.96 -> 2.0253072 | E5: =SUM(E8:E50)/1800/0.96 -> 2.0856481 | G5: grams
A8: 1 | B8: 23 | C8: 21 | D8: =(E8*2.02/2.08) -> 21.365385 | E8: 22 | F8: 17 | G8: 22
A9: 2 | B9: 25 | C9: 24 | D9: 23 | E9: 24 | F9: 21 | G9: 24
A10: 3 | B10: 27 | C10: 26 | D10: =(E10*2.02/2.08) -> 26.221154 | E10: 27 | F10: 26 | G10: 26
A11: 4 | B11: 30 | C11: 29 | D11: =(E11*2.02/2.08) -> 28.163462 | E11: 29 | F11: 29 | G11: 28
A12: 5 | B12: 32 | C12: 31 | D12: =(E12*2.02/2.08) -> 30.105769 | E12: 31 | F12: 32 | G12: 30
A13: 6 | B13: 34 | C13: 33 | D13: =(E13*2.02/2.08) -> 32.048077 | E13: 33 | F13: 35 | G13: 32
A14: 7 | B14: 36 | C14: 35 | D14: =(E14*2.02/2.08) -> 33.990385 | E14: 35 | F14: 38 | G14: 34 | H14: =SUM(G8:G14)/7 -> 28
A15: 8 | B15: 38 | C15: 36 | D15: =(E15*2.02/2.08) -> 35.932692 | E15: 37 | F15: 41 | G15: 36
A16: 9 | B16: 40 | C16: 39 | D16: =(E16*2.02/2.08) -> 37.875 | E16: 39 | F16: 44 | G16: 40
A17: 10 | B17: 43 | C17: 41 | D17: =(E17*2.02/2.08) -> 40.788462 | E17: 42 | F17: 47 | G17: 45
A18: 11 | B18: 45 | C18: 43 | D18: =(E18*2.02/2.08) -> 42.730769 | E18: 44 | F18: 51 | G18: 50
A19: 12 | B19: 48 | C19: 46 | D19: =(E19*2.02/2.08) -> 45.644231 | E19: 47 | F19: 55 | G19: 55
A20: 13 | B20: 50 | C20: 48 | D20: =(E20*2.02/2.08) -> 47.586538 | E20: 49 | F20: 59 | G20: 60
A21: 14 | B21: 54 | C21: 52 | D21: =(E21*2.02/2.08) -> 51.471154 | E21: 53 | F21: 63 | G21: 65 | H21: =SUM(G15:G21)/7 -> 50.142857
A22: 15 | B22: 57 | C22: 55 | D22: =(E22*2.02/2.08) -> 54.384615 | E22: 56 | F22: 66 | G22: 74
A23: 16 | B23: 61 | C23: 58 | D23: =(E23*2.02/2.08) -> 57.298077 | E23: 59 | F23: 70 | G23: 75
A24: 17 | B24: 66 | C24: 62 | D24: =(E24*2.02/2.08) -> 62.153846 | E24: 64 | F24: 73 | G24: 80
A25: 18 | B25: 69 | C25: 66 | D25: =(E25*2.02/2.08) -> 66.038462 | E25: 68 | F25: 77 | G25: 87
A26: 19 | B26: 75 | C26: 72 | D26: =(E26*2.02/2.08) -> 70.894231 | E26: 73 | F26: 81 | G26: 93
A27: 20 | B27: 79 | C27: 77 | D27: =(E27*2.02/2.08) -> 75.75 | E27: 78 | F27: 85 | G27: 97
A28: 21 | B28: 84 | C28: 80 | D28: =(E28*2.02/2.08) -> 79.634615 | E28: 82 | F28: 89 | G28: 103 | H28: =SUM(G22:G28)/7 -> 87
A29: 22 | B29: 90 | C29: 85 | D29: =(E29*2.02/2.08) -> 84.490385 | E29: 87 | F29: 93 | G29: 107
A30: 23 | B30: 94 | C30: 90 | D30: =(E30*2.02/2.08) -> 89.346154 | E30: 92 | F30: 97 | G30: 113
A31: 24 | B31: 98 | C31: 94 | D31: =(E31*2.02/2.08) -> 93.230769 | E31: 96 | F31: 101 | G31: 118
A32: 25 | B32: 101 | C32: 98 | D32: =(E32*2.02/2.08) -> 97.115385 | E32: 100 | F32: 105 | G32: 122
A33: 26 | B33: 106 | C33: 100 | D33: =(E33*2.02/2.08) -> 100.02885 | E33: 103 | F33: 109 | G33: 128
A34: 27 | B34: 109 | C34: 103 | D34: =(E34*2.02/2.08) -> 102.94231 | E34: 106 | F34: 113 | G34: 134
A35: 28 | B35: 113 | C35: 105 | D35: =(E35*2.02/2.08) -> 105.85577 | E35: 109 | F35: 116 | G35: 139 | H35: =SUM(G29:G35)/7 -> 123
A36: 29 | B36: 117 | C36: 109 | D36: =(E36*2.02/2.08) -> 109.74038 | E36: 113 | F36: 119 | G36: 140
A37: 30 | B37: 119 | C37: 111 | D37: =(E37*2.02/2.08) -> 111.68269 | E37: 115 | F37: 123 | G37: 142
A38: 31 | B38: 122 | C38: 112 | D38: =(E38*2.02/2.08) -> 113.625 | E38: 117 | F38: 126 | G38: 149
A39: 32 | B39: 123 | C39: 116 | D39: =(E39*2.02/2.08) -> 115.56731 | E39: 119 | F39: 130 | G39: 153
A40: 33 | B40: 127 | C40: 118 | D40: =(E40*2.02/2.08) -> 118.48077 | E40: 122 | F40: 134 | G40: 158
A41: 34 | B41: 129 | C41: 120 | D41: =(E41*2.02/2.08) -> 120.42308 | E41: 124 | F41: 137 | G41: 163
A42: 35 | B42: 131 | C42: 122 | D42: =(E42*2.02/2.08) -> 123.33654 | E42: 127 | F42: 140 | G42: 165 | H42: =SUM(G36:G42)/7 -> 152.85714
A43: 36 | B43: 133 | C43: 124 | D43: =(E43*2.02/2.08) -> 124.30769 | E43: 128 | F43: 143 | G43: 168
...

Sheet  SHED 1 & 2
A1: GROWER : | N1: DOUBLE B | P1: SHED | R1: 1 & 2
A2: NO. OF BIRDS | N2: =N4+N5+N6 -> 80800 | R2: STR ALL. | S2: =(N2*0.325) -> 26260 | T2: KG.
A3: PLACEMENT | N3: 46101 | R3: GWR ALL. | S3: =(N2*1.15) -> 92920 | T3: KG. | Y3: SHED 1
B4: SHED 1 | N4: 40500 | R4: FIN ALL. | S4: =(N2*1.7) -> 137360 | T4: KG. | U4: WDW ALL C 10 | Y4: SHED 2
B5: SHED 2 | N5: 40300 | R5: WDW ALL. | S5: =N2*1.5 -> 121200 | T5: KG.
AC6: OVERALL | AD6: % WGHT | AF6: % WGHT
O7: TOTAL | AB7: FEED | AC7: FEED | AD7: MIXED | AF7: MIXED
A8: AGE | B8: DAY | N8: DATE | O8: FEED | P8: FEED | R8: FEED | S8: FEED | T8: FEED | U8: SILO | V8: SILOST | W8: SILO | X8: SILO | Y8: CATCH | Z8: BIRDS | AA8: SHED | AB8: DIFF | AC8: DISCREPANCY | AD8: SHED 1 | AE8: Weight(Kg) | AF8: SHED 2 | AG8: Weight(Kg)
N9: 43297 | O9: DEL. | P9: ORDERED | Q9: SILO | R9: ALLOC. | S9: USAGE | T9: ON HAND | U9: TOTAL | V9: A | W9: B | X9: C | Y9: MORTS | Z9: LEFT | AA9: # | AH9: AGE
R12: =S2 -> 26260 | S12: 0 | T12: =IF((U12>0),(U12-S12+P12),(T11-S12+P12)) -> 0 | U12: =(V12+X12+W12) -> 0
A13: 1 | B13: =N3 -> 46101 | O13: =P13 -> 24000 | P13: 24000 | Q13: a | R13: =R12-P13 -> 2260 | S13: =('Consumption Guide'!G8*Z13)/1000 -> 1777.6 | T13: =IF((U13>0),(U13-S13+P13),(T12-S13+P13)) -> 22222.4 | U13: =(V13+X13+W13) -> 0 | Z13: =SUM(N2-Y13) -> 80800
A14: =A13+1 -> 2 | B14: =B13+1 -> 46102 | O14: =O13+P14 -> 24000 | R14: =R13-P14 -> 2260 | S14: =('Consumption Guide'!G9*Z14)/1000 -> 1939.2 | T14: =IF((U14>0),(U14-S14+P14),(T13-S14+P14)) -> 20283.2 | U14: =(V14+X14+W14) -> 0 | Z14: =SUM(Z13-Y14) -> 80800 | AC14: =AB14+AC13 -> 0
A15: =A14+1 -> 3 | B15: =B14+1 -> 46103 | O15: =O14+P15 -> 24000 | R15: =R14-P15 -> 2260 | S15: =('Consumption Guide'!G10*Z15)/1000 -> 2100.8 | T15: =IF((U15>0),(U15-S15+P15),(T14-S15+P15)) -> 18182.4 | U15: =(V15+X15+W15) -> 0 | Z15: =SUM(Z14-Y15) -> 80800 | AC15: =AB15+AC14 -> 0
A16: =A15+1 -> 4 | B16: =B15+1 -> 46104 | O16: =O15+P16 -> 24000 | R16: =R15-P16 -> 2260 | S16: =('Consumption Guide'!G11*Z16)/1000 -> 2262.4 | T16: =IF((U16>0),(U16-S16+P16),(T15-S16+P16)) -> 15920 | U16: =(V16+X16+W16) -> 0 | Z16: =SUM(Z15-Y16) -> 80800 | AC16: =AB16+AC15 -> 0
A17: =A16+1 -> 5 | B17: =B16+1 -> 46105 | O17: =O16+P17 -> 24000 | R17: =R16-P17 -> 2260 | S17: =('Consumption Guide'!G12*Z17)/1000 -> 2424 | T17: =IF((U17>0),(U17-S17+P17),(T16-S17+P17)) -> 13496 | U17: =(V17+X17+W17) -> 0 | Z17: =SUM(Z16-Y17) -> 80800 | AC17: =AB17+AC16 -> 0
A18: =A17+1 -> 6 | B18: =B17+1 -> 46106 | O18: =O17+P18 -> 24000 | R18: =R17-P18 -> 2260 | S18: =('Consumption Guide'!G13*Z18)/1000 -> 2585.6 | T18: =IF((U18>0),(U18-S18+P18),(T17-S18+P18)) -> 43414.4 | U18: =(V18+X18+W18) -> 46000 | V18: 18000 | W18: 22000 | X18: 6000 | Z18: =SUM(Z17-Y18) -> 80800 | AC18: =AB18+AC17 -> 0
A19: =A18+1 -> 7 | B19: =B18+1 -> 46107 | O19: =O18+P19 -> 40000 | P19: 16000 | R19: =R18-P19 -> -13740 | S19: =('Consumption Guide'!G14*Z19)/1000 -> 2747.2 | T19: =IF((U19>0),(U19-S19+P19),(T18-S19+P19)) -> 59252.8 | U19: =(V19+X19+W19) -> 46000 | V19: 18000 | W19: 22000 | X19: 6000 | Z19: =SUM(Z18-Y19) -> 80800 | AC19: =AB19+AC18 -> 0
A20: 8 | B20: =B19+1 -> 46108 | O20: =O19+P20 -> 40000 | R20: =R19-P20 -> -13740 | S20: =('Consumption Guide'!G15*Z20)/1000 -> 2908.8 | T20: =IF((U20>0),(U20-S20+P20),(T19-S20+P20)) -> 49091.2 | U20: =(V20+X20+W20) -> 52000 | V20: 16000 | W20: 20000 | X20: 16000 | Z20: =SUM(Z19-Y20) -> 80800 | AC20: =AB20+AC19 -> 0
A21: =A20+1 -> 9 | B21: =B20+1 -> 46109 | O21: =O20+P21 -> 40000 | R21: =R20-P21 -> -13740 | S21: =('Consumption Guide'!G16*Z21)/1000 -> 3232 | T21: =IF((U21>0),(U21-S21+P21),(T20-S21+P21)) -> 45859.2 | U21: =(V21+X21+W21) -> 0 | Z21: =SUM(Z20-Y21) -> 80800 | AC21: =AB21+AC20 -> 0
A22: =A21+1 -> 10 | B22: =B21+1 -> 46110 | O22: =O21+P22 -> 56000 | P22: 16000 | R22: 96480 | S22: =('Consumption Guide'!G17*Z22)/1000 -> 3636 | T22: =IF((U22>0),(U22-S22+P22),(T21-S22+P22)) -> 58223.2 | U22: =(V22+X22+W22) -> 0 | Z22: =SUM(Z21-Y22) -> 80800 | AC22: =AB22+AC21 -> 0
A23: =A22+1 -> 11 | B23: =B22+1 -> 46111 | O23: =O22+P23 -> 56000 | R23: =S3-P23 -> 92920 | S23: =('Consumption Guide'!G18*Z23)/1000 -> 4040 | T23: =IF((U23>0),(U23-S23+P23),(T22-S23+P23)) -> 43960 | U23: =(V23+X23+W23) -> 48000 | V23: 12000 | W23: 20000 | X23: 16000 | Z23: =SUM(Z22-Y23) -> 80800 | AC23: =AB23+AC22 -> 0
A24: =A23+1 -> 12 | B24: =B23+1 -> 46112 | O24: =O23+P24 -> 56000 | R24: =R23-P24 -> 92920 | S24: =('Consumption Guide'!G19*Z24)/1000 -> 4444 | T24: =IF((U24>0),(U24-S24+P24),(T23-S24+P24)) -> 39516 | U24: =(V24+X24+W24) -> 0 | Z24: =SUM(Z23-Y24) -> 80800 | AC24: =AB24+AC23 -> 0
A25: =A24+1 -> 13 | B25: =B24+1 -> 46113 | O25: =O24+P25 -> 56000 | R25: =R24-P25 -> 92920 | S25: =('Consumption Guide'!G20*Z25)/1000 -> 4848 | T25: =IF((U25>0),(U25-S25+P25),(T24-S25+P25)) -> 34668 | U25: =(V25+X25+W25) -> 0 | Z25: =SUM(Z24-Y25) -> 80800 | AC25: =AB25+AC24 -> 0
A26: =A25+1 -> 14 | B26: =B25+1 -> 46114 | O26: =O25+P26 -> 72000 | P26: 16000 | R26: =R25-P26 -> 76920 | S26: =('Consumption Guide'!G21*Z26)/1000 -> 5252 | T26: =IF((U26>0),(U26-S26+P26),(T25-S26+P26)) -> 45416 | U26: =(V26+X26+W26) -> 0 | Z26: =SUM(Z25-Y26) -> 80800 | AC26: =AB26+AC25 -> 0
A27: =A26+1 -> 15 | B27: =B26+1 -> 46115 | O27: =O26+P27 -> 72000 | R27: =R26-P27 -> 76920 | S27: =('Consumption Guide'!G22*Z27)/1000 -> 5979.2 | T27: =IF((U27>0),(U27-S27+P27),(T26-S27+P27)) -> 39436.8 | U27: =(V27+X27+W27) -> 0 | Z27: =SUM(Z26-Y27) -> 80800 | AC27: =AB27+AC26 -> 0
A28: =A27+1 -> 16 | B28: =B27+1 -> 46116 | O28: =O27+P28 -> 72000 | R28: =R27-P28 -> 76920 | S28: =('Consumption Guide'!G23*Z28)/1000 -> 6060 | T28: =IF((U28>0),(U28-S28+P28),(T27-S28+P28)) -> 33376.8 | U28: =(V28+X28+W28) -> 0 | Z28: =SUM(Z27-Y28) -> 80800 | AC28: =AB28+AC27 -> 0
A29: =A28+1 -> 17 | B29: =B28+1 -> 46117 | O29: =O28+P29 -> 94000 | P29: 22000 | R29: =R28-P29 -> 54920 | S29: =('Consumption Guide'!G24*Z29)/1000 -> 6464 | T29: =IF((U29>0),(U29-S29+P29),(T28-S29+P29)) -> 48912.8 | U29: =(V29+X29+W29) -> 0 | Z29: =SUM(Z28-Y29) -> 80800 | AC29: =AB29+AC28 -> 0
A30: =A29+1 -> 18 | B30: =B29+1 -> 46118 | O30: =O29+P30 -> 94000 | R30: =R29-P30 -> 54920 | S30: =('Consumption Guide'!G25*Z30)/1000 -> 7029.6 | T30: =IF((U30>0),(U30-S30+P30),(T29-S30+P30)) -> 41883.2 | U30: =(V30+X30+W30) -> 0 | Z30: =SUM(Z29-Y30) -> 80800 | AC30: =AB30+AC29 -> 0
A31: =A30+1 -> 19 | B31: =B30+1 -> 46119 | O31: =O30+P31 -> 94000 | R31: =R30-P31 -> 54920 | S31: =('Consumption Guide'!G26*Z31)/1000 -> 7514.4 | T31: =IF((U31>0),(U31-S31+P31),(T30-S31+P31)) -> 34368.8 | U31: =(V31+X31+W31) -> 0 | Z31: =SUM(Z30-Y31) -> 80800 | AC31: =AB31+AC30 -> 0
A32: =A31+1 -> 20 | B32: =B31+1 -> 46120 | O32: =O31+P32 -> 94000 | R32: =R31-P32 -> 54920 | S32: =('Consumption Guide'!G27*Z32)/1000 -> 7837.6 | T32: =IF((U32>0),(U32-S32+P32),(T31-S32+P32)) -> 26531.2 | U32: =(V32+X32+W32) -> 0 | Z32: =SUM(Z31-Y32) -> 80800 | AC32: =AB32+AC31 -> 0
A33: =A32+1 -> 21 | B33: =B32+1 -> 46121 | O33: =O32+P33 -> 94000 | R33: =R32-P33 -> 54920 | S33: =('Consumption Guide'!G28*Z33)/1000 -> 8322.4 | T33: =IF((U33>0),(U33-S33+P33),(T32-S33+P33)) -> 18208.8 | U33: =(V33+X33+W33) -> 0 | Z33: =SUM(Z32-Y33) -> 80800 | AC33: =AB33+AC32 -> 0
A34: =A33+1 -> 22 | B34: =B33+1 -> 46122 | O34: =O33+P34 -> 94000 | R34: =R33-P34 -> 54920 | S34: =('Consumption Guide'!G29*Z34)/1000 -> 8645.6 | T34: =IF((U34>0),(U34-S34+P34),(T33-S34+P34)) -> 9563.2 | U34: =(V34+X34+W34) -> 0 | Z34: =SUM(Z33-Y34) -> 80800 | AC34: =AB34+AC33 -> 0
A35: =A34+1 -> 23 | B35: =B34+1 -> 46123 | O35: =O34+P35 -> 94000 | R35: =R34-P35 -> 54920 | S35: =('Consumption Guide'!G30*Z35)/1000 -> 9130.4 | T35: =IF((U35>0),(U35-S35+P35),(T34-S35+P35)) -> 432.8 | U35: =(V35+X35+W35) -> 0 | Z35: =SUM(Z34-Y35) -> 80800 | AC35: =AB35+AC34 -> 0
A36: =A35+1 -> 24 | B36: =B35+1 -> 46124 | O36: =O35+P36 -> 94000 | R36: =R35-P36 -> 54920 | S36: =('Consumption Guide'!G31*Z36)/1000 -> 9534.4 | T36: =IF((U36>0),(U36-S36+P36),(T35-S36+P36)) -> -9101.6 | U36: =(V36+X36+W36) -> 0 | Z36: =SUM(Z35-Y36) -> 80800 | AC36: =AB36+AC35 -> 0
A37: =A36+1 -> 25 | B37: =B36+1 -> 46125 | O37: =O36+P37 -> 94000 | R37: =S4-P36 -> 137360 | S37: =('Consumption Guide'!G32*Z37)/1000 -> 9857.6 | T37: =IF((U37>0),(U37-S37+P37),(T36-S37+P37)) -> -18959.2 | U37: =(V37+X37+W37) -> 0 | Z37: =SUM(Z36-Y37) -> 80800 | AC37: =AB37+AC36 -> 0
A38: =A37+1 -> 26 | B38: =B37+1 -> 46126 | O38: =O37+P38 -> 94000 | R38: =R37-P38 -> 137360 | S38: =('Consumption Guide'!G33*Z38)/1000 -> 10342.4 | T38: =IF((U38>0),(U38-S38+P38),(T37-S38+P38)) -> -29301.6 | U38: =(V38+X38+W38) -> 0 | Z38: =SUM(Z37-Y38) -> 80800 | AC38: =AB38+AC37 -> 0
A39: =A38+1 -> 27 | B39: =B38+1 -> 46127 | O39: =O38+P39 -> 94000 | R39: =R38-P39 -> 137360 | S39: =('Consumption Guide'!G34*Z39)/1000 -> 10827.2 | T39: =IF((U39>0),(U39-S39+P39),(T38-S39+P39)) -> -40128.8 | U39: =(V39+X39+W39) -> 0 | Z39: =SUM(Z38-Y39) -> 80800 | AC39: =AB39+AC38 -> 0
A40: =A39+1 -> 28 | B40: =B39+1 -> 46128 | O40: =O39+P40 -> 94000 | R40: =R39-P40 -> 137360 | S40: =('Consumption Guide'!G35*Z40)/1000 -> 11231.2 | T40: =IF((U40>0),(U40-S40+P40),(T39-S40+P40)) -> -51360 | U40: =(V40+X40+W40) -> 0 | Z40: =SUM(Z39-Y40) -> 80800 | AC40: =AB40+AC39 -> 0
A41: =A40+1 -> 29 | B41: =B40+1 -> 46129 | O41: =O40+P41 -> 94000 | R41: =R40-P41 -> 137360 | S41: =('Consumption Guide'!G36*Z41)/1000 -> 11312 | T41: =IF((U41>0),(U41-S41+P41),(T40-S41+P41)) -> -62672 | U41: =(V41+X41+W41) -> 0 | Z41: =SUM(Z40-Y41) -> 80800 | AC41: =AB41+AC40 -> 0
A42: =A41+1 -> 30 | B42: =B41+1 -> 46130 | O42: =O41+P42 -> 94000 | R42: =R41-P42 -> 137360 | S42: =('Consumption Guide'!G37*Z42)/1000 -> 11473.6 | T42: =IF((U42>0),(U42-S42+P42),(T41-S42+P42)) -> -74145.6 | U42: =(V42+X42+W42) -> 0 | Z42: =SUM(Z41-Y42) -> 80800 | AC42: =AB42+AC41 -> 0
...

Sheet SHED  3 & 4 
A1: GROWER : | C1: DOUBLE B | E1: SHED | G1: 3 & 4
A2: NO. OF BIRDS | C2: 80000 | G2: STR ALL. | H2: =(C2*0.325) -> 26000 | I2: KG.
A3: PLACEMENT | C3: 46101 | G3: GWR ALL. | H3: =(C2*1.15) -> 92000 | I3: KG. | N3: SHED 3
B4: SHED 3 | C4: 39543 | G4: FIN ALL. | H4: =(C2*1.7) -> 136000 | I4: KG. | J4: WDW ALL C 10 | N4: SHED 4
B5: SHED 4 | C5: 40100 | G5: WDW ALL. | H5: =C2*1.5 -> 120000 | I5: KG.
R6: OVERALL | S6: % WGHT | U6: % WGHT
D7: TOTAL | Q7: FEED | R7: FEED | S7: MIXED | U7: MIXED
A8: AGE | B8: DAY | C8: DATE | D8: FEED | E8: FEED | G8: FEED | H8: FEED | I8: FEED | J8: SILO | K8: SILOST | L8: SILO | M8: SILO | N8: CATCH | O8: BIRDS | P8: SHED | Q8: DIFF | R8: DISCREPANCY | S8: SHED 1 | T8: Weight(Kg) | U8: SHED 2 | V8: Weight(Kg)
C9: 43297 | D9: DEL. | E9: ORDERED | F9: SILO | G9: ALLOC. | H9: USAGE | I9: ON HAND | J9: TOTAL | K9: A | L9: B | M9: C | N9: MORTS | O9: LEFT | P9: # | W9: AGE
G12: =H2 -> 26000 | H12: 0 | I12: =IF((J12>0),(J12-H12+E12),(I11-H12+E12)) -> 0 | J12: =(K12+M12+L12) -> 0
A13: 1 | B13: =C3 -> 46101 | D13: =E13 -> 24000 | E13: 24000 | F13: a | G13: =G12-E13 -> 2000 | H13: =('Consumption Guide'!G8*O13)/1000 -> 1760 | I13: =IF((J13>0),(J13-H13+E13),(I12-H13+E13)) -> 22240 | J13: =(K13+M13+L13) -> 0 | O13: =SUM(C2-N13) -> 80000
A14: =A13+1 -> 2 | B14: =B13+1 -> 46102 | D14: =D13+E14 -> 24000 | G14: =G13-E14 -> 2000 | H14: =('Consumption Guide'!G9*O14)/1000 -> 1920 | I14: =IF((J14>0),(J14-H14+E14),(I13-H14+E14)) -> 20320 | J14: =(K14+M14+L14) -> 0 | O14: =SUM(O13-N14) -> 80000 | R14: =Q14+R13 -> 0
A15: =A14+1 -> 3 | B15: =B14+1 -> 46103 | D15: =D14+E15 -> 24000 | G15: =G14-E15 -> 2000 | H15: =('Consumption Guide'!G10*O15)/1000 -> 2080 | I15: =IF((J15>0),(J15-H15+E15),(I14-H15+E15)) -> 18240 | J15: =(K15+M15+L15) -> 0 | O15: =SUM(O14-N15) -> 80000 | R15: =Q15+R14 -> 0
A16: =A15+1 -> 4 | B16: =B15+1 -> 46104 | D16: =D15+E16 -> 24000 | G16: =G15-E16 -> 2000 | H16: =('Consumption Guide'!G11*O16)/1000 -> 2240 | I16: =IF((J16>0),(J16-H16+E16),(I15-H16+E16)) -> 16000 | J16: =(K16+M16+L16) -> 0 | O16: =SUM(O15-N16) -> 80000 | R16: =Q16+R15 -> 0
A17: =A16+1 -> 5 | B17: =B16+1 -> 46105 | D17: =D16+E17 -> 24000 | G17: =G16-E17 -> 2000 | H17: =('Consumption Guide'!G12*O17)/1000 -> 2400 | I17: =IF((J17>0),(J17-H17+E17),(I16-H17+E17)) -> 13600 | J17: =(K17+M17+L17) -> 0 | O17: =SUM(O16-N17) -> 80000 | R17: =Q17+R16 -> 0
A18: =A17+1 -> 6 | B18: =B17+1 -> 46106 | D18: =D17+E18 -> 24000 | G18: =G17-E18 -> 2000 | H18: =('Consumption Guide'!G13*O18)/1000 -> 2560 | I18: =IF((J18>0),(J18-H18+E18),(I17-H18+E18)) -> 43440 | J18: =(K18+M18+L18) -> 46000 | K18: 18000 | L18: 22000 | M18: 6000 | O18: =SUM(O17-N18) -> 80000 | R18: =Q18+R17 -> 0
A19: =A18+1 -> 7 | B19: =B18+1 -> 46107 | D19: =D18+E19 -> 40000 | E19: 16000 | G19: =G18-E19 -> -14000 | H19: =('Consumption Guide'!G14*O19)/1000 -> 2720 | I19: =IF((J19>0),(J19-H19+E19),(I18-H19+E19)) -> 57280 | J19: =(K19+M19+L19) -> 44000 | K19: 18000 | L19: 20000 | M19: 6000 | O19: =SUM(O18-N19) -> 80000 | R19: =Q19+R18 -> 0
A20: 8 | B20: =B19+1 -> 46108 | D20: =D19+E20 -> 40000 | G20: =G19-E20 -> -14000 | H20: =('Consumption Guide'!G15*O20)/1000 -> 2880 | I20: =IF((J20>0),(J20-H20+E20),(I19-H20+E20)) -> 51120 | J20: =(K20+M20+L20) -> 54000 | K20: 18000 | L20: 20000 | M20: 16000 | O20: =SUM(O19-N20) -> 80000 | R20: =Q20+R19 -> 0
A21: =A20+1 -> 9 | B21: =B20+1 -> 46109 | D21: =D20+E21 -> 40000 | G21: =G20-E21 -> -14000 | H21: =('Consumption Guide'!G16*O21)/1000 -> 3200 | I21: =IF((J21>0),(J21-H21+E21),(I20-H21+E21)) -> 47920 | J21: =(K21+M21+L21) -> 0 | O21: =SUM(O20-N21) -> 80000 | R21: =Q21+R20 -> 0
A22: =A21+1 -> 10 | B22: =B21+1 -> 46110 | D22: =D21+E22 -> 56000 | E22: 16000 | G22: 96480 | H22: =('Consumption Guide'!G17*O22)/1000 -> 3600 | I22: =IF((J22>0),(J22-H22+E22),(I21-H22+E22)) -> 60320 | J22: =(K22+M22+L22) -> 0 | O22: =SUM(O21-N22) -> 80000 | R22: =Q22+R21 -> 0
A23: =A22+1 -> 11 | B23: =B22+1 -> 46111 | D23: =D22+E23 -> 56000 | G23: =H3-E23 -> 92000 | H23: =('Consumption Guide'!G18*O23)/1000 -> 4000 | I23: =IF((J23>0),(J23-H23+E23),(I22-H23+E23)) -> 46000 | J23: =(K23+M23+L23) -> 50000 | K23: 14000 | L23: 20000 | M23: 16000 | O23: =SUM(O22-N23) -> 80000 | R23: =Q23+R22 -> 0
A24: =A23+1 -> 12 | B24: =B23+1 -> 46112 | D24: =D23+E24 -> 56000 | G24: =G23-E24 -> 92000 | H24: =('Consumption Guide'!G19*O24)/1000 -> 4400 | I24: =IF((J24>0),(J24-H24+E24),(I23-H24+E24)) -> 41600 | J24: =(K24+M24+L24) -> 0 | O24: =SUM(O23-N24) -> 80000 | R24: =Q24+R23 -> 0
A25: =A24+1 -> 13 | B25: =B24+1 -> 46113 | D25: =D24+E25 -> 56000 | G25: =G24-E25 -> 92000 | H25: =('Consumption Guide'!G20*O25)/1000 -> 4800 | I25: =IF((J25>0),(J25-H25+E25),(I24-H25+E25)) -> 36800 | J25: =(K25+M25+L25) -> 0 | O25: =SUM(O24-N25) -> 80000 | R25: =Q25+R24 -> 0
A26: =A25+1 -> 14 | B26: =B25+1 -> 46114 | D26: =D25+E26 -> 72000 | E26: 16000 | G26: =G25-E26 -> 76000 | H26: =('Consumption Guide'!G21*O26)/1000 -> 5200 | I26: =IF((J26>0),(J26-H26+E26),(I25-H26+E26)) -> 47600 | J26: =(K26+M26+L26) -> 0 | O26: =SUM(O25-N26) -> 80000 | R26: =Q26+R25 -> 0
A27: =A26+1 -> 15 | B27: =B26+1 -> 46115 | D27: =D26+E27 -> 72000 | G27: =G26-E27 -> 76000 | H27: =('Consumption Guide'!G22*O27)/1000 -> 5920 | I27: =IF((J27>0),(J27-H27+E27),(I26-H27+E27)) -> 41680 | J27: =(K27+M27+L27) -> 0 | O27: =SUM(O26-N27) -> 80000 | R27: =Q27+R26 -> 0
A28: =A27+1 -> 16 | B28: =B27+1 -> 46116 | D28: =D27+E28 -> 72000 | G28: =G27-E28 -> 76000 | H28: =('Consumption Guide'!G23*O28)/1000 -> 6000 | I28: =IF((J28>0),(J28-H28+E28),(I27-H28+E28)) -> 35680 | J28: =(K28+M28+L28) -> 0 | O28: =SUM(O27-N28) -> 80000 | R28: =Q28+R27 -> 0
A29: =A28+1 -> 17 | B29: =B28+1 -> 46117 | D29: =D28+E29 -> 94000 | E29: 22000 | G29: =G28-E29 -> 54000 | H29: =('Consumption Guide'!G24*O29)/1000 -> 6400 | I29: =IF((J29>0),(J29-H29+E29),(I28-H29+E29)) -> 51280 | J29: =(K29+M29+L29) -> 0 | O29: =SUM(O28-N29) -> 80000 | R29: =Q29+R28 -> 0
A30: =A29+1 -> 18 | B30: =B29+1 -> 46118 | D30: =D29+E30 -> 94000 | G30: =G29-E30 -> 54000 | H30: =('Consumption Guide'!G25*O30)/1000 -> 6960 | I30: =IF((J30>0),(J30-H30+E30),(I29-H30+E30)) -> 44320 | J30: =(K30+M30+L30) -> 0 | O30: =SUM(O29-N30) -> 80000 | R30: =Q30+R29 -> 0
A31: =A30+1 -> 19 | B31: =B30+1 -> 46119 | D31: =D30+E31 -> 94000 | G31: =G30-E31 -> 54000 | H31: =('Consumption Guide'!G26*O31)/1000 -> 7440 | I31: =IF((J31>0),(J31-H31+E31),(I30-H31+E31)) -> 36880 | J31: =(K31+M31+L31) -> 0 | O31: =SUM(O30-N31) -> 80000 | R31: =Q31+R30 -> 0
A32: =A31+1 -> 20 | B32: =B31+1 -> 46120 | D32: =D31+E32 -> 94000 | G32: =G31-E32 -> 54000 | H32: =('Consumption Guide'!G27*O32)/1000 -> 7760 | I32: =IF((J32>0),(J32-H32+E32),(I31-H32+E32)) -> 29120 | J32: =(K32+M32+L32) -> 0 | O32: =SUM(O31-N32) -> 80000 | R32: =Q32+R31 -> 0
A33: =A32+1 -> 21 | B33: =B32+1 -> 46121 | D33: =D32+E33 -> 94000 | G33: =G32-E33 -> 54000 | H33: =('Consumption Guide'!G28*O33)/1000 -> 8240 | I33: =IF((J33>0),(J33-H33+E33),(I32-H33+E33)) -> 20880 | J33: =(K33+M33+L33) -> 0 | O33: =SUM(O32-N33) -> 80000 | R33: =Q33+R32 -> 0
A34: =A33+1 -> 22 | B34: =B33+1 -> 46122 | D34: =D33+E34 -> 94000 | G34: =G33-E34 -> 54000 | H34: =('Consumption Guide'!G29*O34)/1000 -> 8560 | I34: =IF((J34>0),(J34-H34+E34),(I33-H34+E34)) -> 12320 | J34: =(K34+M34+L34) -> 0 | O34: =SUM(O33-N34) -> 80000 | R34: =Q34+R33 -> 0
A35: =A34+1 -> 23 | B35: =B34+1 -> 46123 | D35: =D34+E35 -> 94000 | G35: =G34-E35 -> 54000 | H35: =('Consumption Guide'!G30*O35)/1000 -> 9040 | I35: =IF((J35>0),(J35-H35+E35),(I34-H35+E35)) -> 3280 | J35: =(K35+M35+L35) -> 0 | O35: =SUM(O34-N35) -> 80000 | R35: =Q35+R34 -> 0
A36: =A35+1 -> 24 | B36: =B35+1 -> 46124 | D36: =D35+E36 -> 94000 | G36: =G35-E36 -> 54000 | H36: =('Consumption Guide'!G31*O36)/1000 -> 9440 | I36: =IF((J36>0),(J36-H36+E36),(I35-H36+E36)) -> -6160 | J36: =(K36+M36+L36) -> 0 | O36: =SUM(O35-N36) -> 80000 | R36: =Q36+R35 -> 0
A37: =A36+1 -> 25 | B37: =B36+1 -> 46125 | D37: =D36+E37 -> 94000 | G37: =H4-E36 -> 136000 | H37: =('Consumption Guide'!G32*O37)/1000 -> 9760 | I37: =IF((J37>0),(J37-H37+E37),(I36-H37+E37)) -> -15920 | J37: =(K37+M37+L37) -> 0 | O37: =SUM(O36-N37) -> 80000 | R37: =Q37+R36 -> 0
A38: =A37+1 -> 26 | B38: =B37+1 -> 46126 | D38: =D37+E38 -> 94000 | G38: =G37-E38 -> 136000 | H38: =('Consumption Guide'!G33*O38)/1000 -> 10240 | I38: =IF((J38>0),(J38-H38+E38),(I37-H38+E38)) -> -26160 | J38: =(K38+M38+L38) -> 0 | O38: =SUM(O37-N38) -> 80000 | R38: =Q38+R37 -> 0
A39: =A38+1 -> 27 | B39: =B38+1 -> 46127 | D39: =D38+E39 -> 94000 | G39: =G38-E39 -> 136000 | H39: =('Consumption Guide'!G34*O39)/1000 -> 10720 | I39: =IF((J39>0),(J39-H39+E39),(I38-H39+E39)) -> -36880 | J39: =(K39+M39+L39) -> 0 | O39: =SUM(O38-N39) -> 80000 | R39: =Q39+R38 -> 0
A40: =A39+1 -> 28 | B40: =B39+1 -> 46128 | D40: =D39+E40 -> 94000 | G40: =G39-E40 -> 136000 | H40: =('Consumption Guide'!G35*O40)/1000 -> 11120 | I40: =IF((J40>0),(J40-H40+E40),(I39-H40+E40)) -> -48000 | J40: =(K40+M40+L40) -> 0 | O40: =SUM(O39-N40) -> 80000 | R40: =Q40+R39 -> 0
A41: =A40+1 -> 29 | B41: =B40+1 -> 46129 | D41: =D40+E41 -> 94000 | G41: =G40-E41 -> 136000 | H41: =('Consumption Guide'!G36*O41)/1000 -> 11200 | I41: =IF((J41>0),(J41-H41+E41),(I40-H41+E41)) -> -59200 | J41: =(K41+M41+L41) -> 0 | O41: =SUM(O40-N41) -> 80000 | R41: =Q41+R40 -> 0
A42: =A41+1 -> 30 | B42: =B41+1 -> 46130 | D42: =D41+E42 -> 94000 | G42: =G41-E42 -> 136000 | H42: =('Consumption Guide'!G37*O42)/1000 -> 11360 | I42: =IF((J42>0),(J42-H42+E42),(I41-H42+E42)) -> -70560 | J42: =(K42+M42+L42) -> 0 | O42: =SUM(O41-N42) -> 80000 | R42: =Q42+R41 -> 0
...

Sheet SHED  5 & 6
A1: GROWER : | C1: DOUBLE B | E1: SHED | G1: 5 & 6
A2: NO. OF BIRDS | C2: 80000 | G2: STR ALL. | H2: =(C2*0.325) -> 26000 | I2: KG.
A3: PLACEMENT | C3: 46104 | G3: GWR ALL. | H3: =(C2*1.15) -> 92000 | I3: KG. | N3: SHED 5
B4: SHED 5 | C4: 40100 | G4: FIN ALL. | H4: =(C2*1.7) -> 136000 | I4: KG. | J4: WDW ALL C 10 | N4: SHED 6
B5: SHED 6 | C5: 39200 | G5: WDW ALL. | H5: =C2*1.5 -> 120000 | I5: KG.
R6: OVERALL | S6: % WGHT | U6: % WGHT
D7: TOTAL | Q7: FEED | R7: FEED | S7: MIXED | U7: MIXED
A8: AGE | B8: DAY | C8: DATE | D8: FEED | E8: FEED | G8: FEED | H8: FEED | I8: FEED | J8: SILO | K8: SILOST | L8: SILO | M8: SILO | N8: CATCH | O8: BIRDS | P8: SHED | Q8: DIFF | R8: DISCREPANCY | S8: SHED 1 | T8: Weight(Kg) | U8: SHED 2 | V8: Weight(Kg)
C9: 43297 | D9: DEL. | E9: ORDERED | F9: SILO | G9: ALLOC. | H9: USAGE | I9: ON HAND | J9: TOTAL | K9: A | L9: B | M9: C | N9: MORTS | O9: LEFT | P9: # | W9: AGE
G12: =H2 -> 26000 | H12: 0 | I12: =IF((J12>0),(J12-H12+E12),(I11-H12+E12)) -> 0 | J12: =(K12+M12+L12) -> 0
A13: 1 | B13: =C3 -> 46104 | D13: =E13 -> 24000 | E13: 24000 | F13: a | G13: =G12-E13 -> 2000 | H13: =('Consumption Guide'!G8*O13)/1000 -> 1760 | I13: =IF((J13>0),(J13-H13+E13),(I12-H13+E13)) -> 22240 | J13: =(K13+M13+L13) -> 0 | O13: =SUM(C2-N13) -> 80000
A14: =A13+1 -> 2 | B14: =B13+1 -> 46105 | D14: =D13+E14 -> 24000 | G14: =G13-E14 -> 2000 | H14: =('Consumption Guide'!G9*O14)/1000 -> 1920 | I14: =IF((J14>0),(J14-H14+E14),(I13-H14+E14)) -> 20320 | J14: =(K14+M14+L14) -> 0 | O14: =SUM(O13-N14) -> 80000 | R14: =Q14+R13 -> 0
A15: =A14+1 -> 3 | B15: =B14+1 -> 46106 | D15: =D14+E15 -> 24000 | G15: =G14-E15 -> 2000 | H15: =('Consumption Guide'!G10*O15)/1000 -> 2080 | I15: =IF((J15>0),(J15-H15+E15),(I14-H15+E15)) -> 47920 | J15: =(K15+M15+L15) -> 50000 | K15: 6000 | L15: 22000 | M15: 22000 | O15: =SUM(O14-N15) -> 80000 | R15: =Q15+R14 -> 0
A16: =A15+1 -> 4 | B16: =B15+1 -> 46107 | D16: =D15+E16 -> 40000 | E16: 16000 | G16: =G15-E16 -> -14000 | H16: =('Consumption Guide'!G11*O16)/1000 -> 2240 | I16: =IF((J16>0),(J16-H16+E16),(I15-H16+E16)) -> 57760 | J16: =(K16+M16+L16) -> 44000 | K16: 6000 | L16: 18000 | M16: 20000 | O16: =SUM(O15-N16) -> 80000 | R16: =Q16+R15 -> 0
A17: =A16+1 -> 5 | B17: =B16+1 -> 46108 | D17: =D16+E17 -> 40000 | G17: =G16-E17 -> -14000 | H17: =('Consumption Guide'!G12*O17)/1000 -> 2400 | I17: =IF((J17>0),(J17-H17+E17),(I16-H17+E17)) -> 51600 | J17: =(K17+M17+L17) -> 54000 | K17: 16000 | L17: 18000 | M17: 20000 | O17: =SUM(O16-N17) -> 80000 | R17: =Q17+R16 -> 0
A18: =A17+1 -> 6 | B18: =B17+1 -> 46109 | D18: =D17+E18 -> 40000 | G18: =G17-E18 -> -14000 | H18: =('Consumption Guide'!G13*O18)/1000 -> 2560 | I18: =IF((J18>0),(J18-H18+E18),(I17-H18+E18)) -> 49040 | J18: =(K18+M18+L18) -> 0 | O18: =SUM(O17-N18) -> 80000 | R18: =Q18+R17 -> 0
A19: =A18+1 -> 7 | B19: =B18+1 -> 46110 | D19: =D18+E19 -> 56000 | E19: 16000 | G19: =G18-E19 -> -30000 | H19: =('Consumption Guide'!G14*O19)/1000 -> 2720 | I19: =IF((J19>0),(J19-H19+E19),(I18-H19+E19)) -> 62320 | J19: =(K19+M19+L19) -> 0 | O19: =SUM(O18-N19) -> 80000 | R19: =Q19+R18 -> 0
A20: 8 | B20: =B19+1 -> 46111 | D20: =D19+E20 -> 56000 | G20: =G19-E20 -> -30000 | H20: =('Consumption Guide'!G15*O20)/1000 -> 2880 | I20: =IF((J20>0),(J20-H20+E20),(I19-H20+E20)) -> 53120 | J20: =(K20+M20+L20) -> 56000 | K20: 18000 | L20: 18000 | M20: 20000 | O20: =SUM(O19-N20) -> 80000 | R20: =Q20+R19 -> 0
A21: =A20+1 -> 9 | B21: =B20+1 -> 46112 | D21: =D20+E21 -> 56000 | G21: =G20-E21 -> -30000 | H21: =('Consumption Guide'!G16*O21)/1000 -> 3200 | I21: =IF((J21>0),(J21-H21+E21),(I20-H21+E21)) -> 49920 | J21: =(K21+M21+L21) -> 0 | O21: =SUM(O20-N21) -> 80000 | R21: =Q21+R20 -> 0
A22: =A21+1 -> 10 | B22: =B21+1 -> 46113 | D22: =D21+E22 -> 56000 | G22: 96480 | H22: =('Consumption Guide'!G17*O22)/1000 -> 3600 | I22: =IF((J22>0),(J22-H22+E22),(I21-H22+E22)) -> 46320 | J22: =(K22+M22+L22) -> 0 | O22: =SUM(O21-N22) -> 80000 | R22: =Q22+R21 -> 0
A23: =A22+1 -> 11 | B23: =B22+1 -> 46114 | D23: =D22+E23 -> 72000 | E23: 16000 | G23: =H3-E23 -> 76000 | H23: =('Consumption Guide'!G18*O23)/1000 -> 4000 | I23: =IF((J23>0),(J23-H23+E23),(I22-H23+E23)) -> 58320 | J23: =(K23+M23+L23) -> 0 | O23: =SUM(O22-N23) -> 80000 | R23: =Q23+R22 -> 0
A24: =A23+1 -> 12 | B24: =B23+1 -> 46115 | D24: =D23+E24 -> 72000 | G24: =G23-E24 -> 76000 | H24: =('Consumption Guide'!G19*O24)/1000 -> 4400 | I24: =IF((J24>0),(J24-H24+E24),(I23-H24+E24)) -> 53920 | J24: =(K24+M24+L24) -> 0 | O24: =SUM(O23-N24) -> 80000 | R24: =Q24+R23 -> 0
A25: =A24+1 -> 13 | B25: =B24+1 -> 46116 | D25: =D24+E25 -> 72000 | G25: =G24-E25 -> 76000 | H25: =('Consumption Guide'!G20*O25)/1000 -> 4800 | I25: =IF((J25>0),(J25-H25+E25),(I24-H25+E25)) -> 49120 | J25: =(K25+M25+L25) -> 0 | O25: =SUM(O24-N25) -> 80000 | R25: =Q25+R24 -> 0
A26: =A25+1 -> 14 | B26: =B25+1 -> 46117 | D26: =D25+E26 -> 94000 | E26: 22000 | G26: =G25-E26 -> 54000 | H26: =('Consumption Guide'!G21*O26)/1000 -> 5200 | I26: =IF((J26>0),(J26-H26+E26),(I25-H26+E26)) -> 65920 | J26: =(K26+M26+L26) -> 0 | O26: =SUM(O25-N26) -> 80000 | R26: =Q26+R25 -> 0
A27: =A26+1 -> 15 | B27: =B26+1 -> 46118 | D27: =D26+E27 -> 94000 | G27: =G26-E27 -> 54000 | H27: =('Consumption Guide'!G22*O27)/1000 -> 5920 | I27: =IF((J27>0),(J27-H27+E27),(I26-H27+E27)) -> 60000 | J27: =(K27+M27+L27) -> 0 | O27: =SUM(O26-N27) -> 80000 | R27: =Q27+R26 -> 0
A28: =A27+1 -> 16 | B28: =B27+1 -> 46119 | D28: =D27+E28 -> 94000 | G28: =G27-E28 -> 54000 | H28: =('Consumption Guide'!G23*O28)/1000 -> 6000 | I28: =IF((J28>0),(J28-H28+E28),(I27-H28+E28)) -> 54000 | J28: =(K28+M28+L28) -> 0 | O28: =SUM(O27-N28) -> 80000 | R28: =Q28+R27 -> 0
A29: =A28+1 -> 17 | B29: =B28+1 -> 46120 | D29: =D28+E29 -> 94000 | G29: =G28-E29 -> 54000 | H29: =('Consumption Guide'!G24*O29)/1000 -> 6400 | I29: =IF((J29>0),(J29-H29+E29),(I28-H29+E29)) -> 47600 | J29: =(K29+M29+L29) -> 0 | O29: =SUM(O28-N29) -> 80000 | R29: =Q29+R28 -> 0
A30: =A29+1 -> 18 | B30: =B29+1 -> 46121 | D30: =D29+E30 -> 94000 | G30: =G29-E30 -> 54000 | H30: =('Consumption Guide'!G25*O30)/1000 -> 6960 | I30: =IF((J30>0),(J30-H30+E30),(I29-H30+E30)) -> 40640 | J30: =(K30+M30+L30) -> 0 | O30: =SUM(O29-N30) -> 80000 | R30: =Q30+R29 -> 0
A31: =A30+1 -> 19 | B31: =B30+1 -> 46122 | D31: =D30+E31 -> 94000 | G31: =G30-E31 -> 54000 | H31: =('Consumption Guide'!G26*O31)/1000 -> 7440 | I31: =IF((J31>0),(J31-H31+E31),(I30-H31+E31)) -> 33200 | J31: =(K31+M31+L31) -> 0 | O31: =SUM(O30-N31) -> 80000 | R31: =Q31+R30 -> 0
A32: =A31+1 -> 20 | B32: =B31+1 -> 46123 | D32: =D31+E32 -> 94000 | G32: =G31-E32 -> 54000 | H32: =('Consumption Guide'!G27*O32)/1000 -> 7760 | I32: =IF((J32>0),(J32-H32+E32),(I31-H32+E32)) -> 25440 | J32: =(K32+M32+L32) -> 0 | O32: =SUM(O31-N32) -> 80000 | R32: =Q32+R31 -> 0
A33: =A32+1 -> 21 | B33: =B32+1 -> 46124 | D33: =D32+E33 -> 94000 | G33: =G32-E33 -> 54000 | H33: =('Consumption Guide'!G28*O33)/1000 -> 8240 | I33: =IF((J33>0),(J33-H33+E33),(I32-H33+E33)) -> 17200 | J33: =(K33+M33+L33) -> 0 | O33: =SUM(O32-N33) -> 80000 | R33: =Q33+R32 -> 0
A34: =A33+1 -> 22 | B34: =B33+1 -> 46125 | D34: =D33+E34 -> 94000 | G34: =G33-E34 -> 54000 | H34: =('Consumption Guide'!G29*O34)/1000 -> 8560 | I34: =IF((J34>0),(J34-H34+E34),(I33-H34+E34)) -> 8640 | J34: =(K34+M34+L34) -> 0 | O34: =SUM(O33-N34) -> 80000 | R34: =Q34+R33 -> 0
A35: =A34+1 -> 23 | B35: =B34+1 -> 46126 | D35: =D34+E35 -> 94000 | G35: =G34-E35 -> 54000 | H35: =('Consumption Guide'!G30*O35)/1000 -> 9040 | I35: =IF((J35>0),(J35-H35+E35),(I34-H35+E35)) -> -400 | J35: =(K35+M35+L35) -> 0 | O35: =SUM(O34-N35) -> 80000 | R35: =Q35+R34 -> 0
A36: =A35+1 -> 24 | B36: =B35+1 -> 46127 | D36: =D35+E36 -> 94000 | G36: =G35-E36 -> 54000 | H36: =('Consumption Guide'!G31*O36)/1000 -> 9440 | I36: =IF((J36>0),(J36-H36+E36),(I35-H36+E36)) -> -9840 | J36: =(K36+M36+L36) -> 0 | O36: =SUM(O35-N36) -> 80000 | R36: =Q36+R35 -> 0
A37: =A36+1 -> 25 | B37: =B36+1 -> 46128 | D37: =D36+E37 -> 94000 | G37: =H4-E36 -> 136000 | H37: =('Consumption Guide'!G32*O37)/1000 -> 9760 | I37: =IF((J37>0),(J37-H37+E37),(I36-H37+E37)) -> -19600 | J37: =(K37+M37+L37) -> 0 | O37: =SUM(O36-N37) -> 80000 | R37: =Q37+R36 -> 0
A38: =A37+1 -> 26 | B38: =B37+1 -> 46129 | D38: =D37+E38 -> 94000 | G38: =G37-E38 -> 136000 | H38: =('Consumption Guide'!G33*O38)/1000 -> 10240 | I38: =IF((J38>0),(J38-H38+E38),(I37-H38+E38)) -> -29840 | J38: =(K38+M38+L38) -> 0 | O38: =SUM(O37-N38) -> 80000 | R38: =Q38+R37 -> 0
A39: =A38+1 -> 27 | B39: =B38+1 -> 46130 | D39: =D38+E39 -> 94000 | G39: =G38-E39 -> 136000 | H39: =('Consumption Guide'!G34*O39)/1000 -> 10720 | I39: =IF((J39>0),(J39-H39+E39),(I38-H39+E39)) -> -40560 | J39: =(K39+M39+L39) -> 0 | O39: =SUM(O38-N39) -> 80000 | R39: =Q39+R38 -> 0
A40: =A39+1 -> 28 | B40: =B39+1 -> 46131 | D40: =D39+E40 -> 94000 | G40: =G39-E40 -> 136000 | H40: =('Consumption Guide'!G35*O40)/1000 -> 11120 | I40: =IF((J40>0),(J40-H40+E40),(I39-H40+E40)) -> -51680 | J40: =(K40+M40+L40) -> 0 | O40: =SUM(O39-N40) -> 80000 | R40: =Q40+R39 -> 0
A41: =A40+1 -> 29 | B41: =B40+1 -> 46132 | D41: =D40+E41 -> 94000 | G41: =G40-E41 -> 136000 | H41: =('Consumption Guide'!G36*O41)/1000 -> 11200 | I41: =IF((J41>0),(J41-H41+E41),(I40-H41+E41)) -> -62880 | J41: =(K41+M41+L41) -> 0 | O41: =SUM(O40-N41) -> 80000 | R41: =Q41+R40 -> 0
A42: =A41+1 -> 30 | B42: =B41+1 -> 46133 | D42: =D41+E42 -> 94000 | G42: =G41-E42 -> 136000 | H42: =('Consumption Guide'!G37*O42)/1000 -> 11360 | I42: =IF((J42>0),(J42-H42+E42),(I41-H42+E42)) -> -74240 | J42: =(K42+M42+L42) -> 0 | O42: =SUM(O41-N42) -> 80000 | R42: =Q42+R41 -> 0
...

Sheet SHED 7 & 8
A1: GROWER : | C1: DOUBLE B | E1: SHED | G1: 7 & 8
A2: NO. OF BIRDS | C2: =C4+C5+C6 -> 94283 | G2: STR ALL. | H2: =(C2*0.325) -> 30641.975 | I2: KG.
A3: PLACEMENT | C3: 46104 | G3: GWR ALL. | H3: =(C2*1.15) -> 108425.45 | I3: KG. | N3: SHED 7
B4: SHED 7 | C4: 47100 | G4: FIN ALL. | H4: =(C2*1.7) -> 160281.1 | I4: KG. | J4: WDW ALL C 10 | N4: SHED 8
B5: SHED 8 | C5: 47183 | G5: WDW ALL. | H5: =C2*1.5 -> 141424.5 | I5: KG.
R6: OVERALL | S6: % WGHT | U6: % WGHT
D7: TOTAL | Q7: FEED | R7: FEED | S7: MIXED | U7: MIXED
A8: AGE | B8: DAY | C8: DATE | D8: FEED | E8: FEED | G8: FEED | H8: FEED | I8: FEED | J8: SILO | K8: SILO | L8: SILO | M8: SILO | N8: CATCH | O8: BIRDS | P8: SHED | Q8: DIFF | R8: DISCREPANCY | S8: SHED 1 | T8: Weight(Kg) | U8: SHED 2 | V8: Weight(Kg)
C9: 43297 | D9: DEL. | E9: ORDERED | F9: SILO | G9: ALLOC. | H9: USAGE | I9: ON HAND | J9: TOTAL | K9: A | L9: B | M9: C | N9: MORTS | O9: LEFT | P9: # | W9: AGE
G12: =H2 -> 30641.975 | H12: 0 | I12: =IF((J12>0),(J12-H12+E12),(I11-H12+E12)) -> 0 | J12: =(K12+M12+L12) -> 0
A13: 1 | B13: =C3 -> 46104 | D13: =E13 -> 29000 | E13: 29000 | F13: a | G13: =G12-E13 -> 1641.975 | H13: =('Consumption Guide'!G8*O13)/1000 -> 2074.226 | I13: =IF((J13>0),(J13-H13+E13),(I12-H13+E13)) -> 26925.774 | J13: =(K13+M13+L13) -> 0 | O13: =SUM(C2-N13) -> 94283
A14: =A13+1 -> 2 | B14: =B13+1 -> 46105 | D14: =D13+E14 -> 29000 | G14: =G13-E14 -> 1641.975 | H14: =('Consumption Guide'!G9*O14)/1000 -> 2262.792 | I14: =IF((J14>0),(J14-H14+E14),(I13-H14+E14)) -> 24662.982 | J14: =(K14+M14+L14) -> 0 | O14: =SUM(O13-N14) -> 94283 | R14: =Q14+R13 -> 0
A15: =A14+1 -> 3 | B15: =B14+1 -> 46106 | D15: =D14+E15 -> 29000 | G15: =G14-E15 -> 1641.975 | H15: =('Consumption Guide'!G10*O15)/1000 -> 2451.358 | I15: =IF((J15>0),(J15-H15+E15),(I14-H15+E15)) -> 57548.642 | J15: =(K15+M15+L15) -> 60000 | K15: 26000 | L15: 14000 | M15: 20000 | O15: =SUM(O14-N15) -> 94283 | R15: =Q15+R14 -> 0
A16: =A15+1 -> 4 | B16: =B15+1 -> 46107 | D16: =D15+E16 -> 45000 | E16: 16000 | G16: =G15-E16 -> -14358.025 | H16: =('Consumption Guide'!G11*O16)/1000 -> 2639.924 | I16: =IF((J16>0),(J16-H16+E16),(I15-H16+E16)) -> 53360.076 | J16: =(K16+M16+L16) -> 40000 | K16: 12000 | L16: 8000 | M16: 20000 | O16: =SUM(O15-N16) -> 94283 | R16: =Q16+R15 -> 0
A17: =A16+1 -> 5 | B17: =B16+1 -> 46108 | D17: =D16+E17 -> 45000 | G17: =G16-E17 -> -14358.025 | H17: =('Consumption Guide'!G12*O17)/1000 -> 2828.49 | I17: =IF((J17>0),(J17-H17+E17),(I16-H17+E17)) -> 45171.51 | J17: =(K17+M17+L17) -> 48000 | K17: 12000 | L17: 16000 | M17: 20000 | O17: =SUM(O16-N17) -> 94283 | R17: =Q17+R16 -> 0
A18: =A17+1 -> 6 | B18: =B17+1 -> 46109 | D18: =D17+E18 -> 45000 | G18: =G17-E18 -> -14358.025 | H18: =('Consumption Guide'!G13*O18)/1000 -> 3017.056 | I18: =IF((J18>0),(J18-H18+E18),(I17-H18+E18)) -> 42154.454 | J18: =(K18+M18+L18) -> 0 | O18: =SUM(O17-N18) -> 94283 | R18: =Q18+R17 -> 0
A19: =A18+1 -> 7 | B19: =B18+1 -> 46110 | D19: =D18+E19 -> 61000 | E19: 16000 | G19: =G18-E19 -> -30358.025 | H19: =('Consumption Guide'!G14*O19)/1000 -> 3205.622 | I19: =IF((J19>0),(J19-H19+E19),(I18-H19+E19)) -> 54948.832 | J19: =(K19+M19+L19) -> 0 | O19: =SUM(O18-N19) -> 94283 | R19: =Q19+R18 -> 0
A20: 8 | B20: =B19+1 -> 46111 | D20: =D19+E20 -> 61000 | G20: =G19-E20 -> -30358.025 | H20: =('Consumption Guide'!G15*O20)/1000 -> 3394.188 | I20: =IF((J20>0),(J20-H20+E20),(I19-H20+E20)) -> 44605.812 | J20: =(K20+M20+L20) -> 48000 | K20: 8000 | L20: 20000 | M20: 20000 | O20: =SUM(O19-N20) -> 94283 | R20: =Q20+R19 -> 0
A21: =A20+1 -> 9 | B21: =B20+1 -> 46112 | D21: =D20+E21 -> 61000 | G21: =G20-E21 -> -30358.025 | H21: =('Consumption Guide'!G16*O21)/1000 -> 3771.32 | I21: =IF((J21>0),(J21-H21+E21),(I20-H21+E21)) -> 40834.492 | J21: =(K21+M21+L21) -> 0 | O21: =SUM(O20-N21) -> 94283 | R21: =Q21+R20 -> 0
A22: =A21+1 -> 10 | B22: =B21+1 -> 46113 | D22: =D21+E22 -> 61000 | G22: 96480 | H22: =('Consumption Guide'!G17*O22)/1000 -> 4242.735 | I22: =IF((J22>0),(J22-H22+E22),(I21-H22+E22)) -> 36591.757 | J22: =(K22+M22+L22) -> 0 | O22: =SUM(O21-N22) -> 94283 | R22: =Q22+R21 -> 0
A23: =A22+1 -> 11 | B23: =B22+1 -> 46114 | D23: =D22+E23 -> 77000 | E23: 16000 | G23: =H3-E23 -> 92425.45 | H23: =('Consumption Guide'!G18*O23)/1000 -> 4714.15 | I23: =IF((J23>0),(J23-H23+E23),(I22-H23+E23)) -> 47877.607 | J23: =(K23+M23+L23) -> 0 | O23: =SUM(O22-N23) -> 94283 | R23: =Q23+R22 -> 0
A24: =A23+1 -> 12 | B24: =B23+1 -> 46115 | D24: =D23+E24 -> 77000 | G24: =G23-E24 -> 92425.45 | H24: =('Consumption Guide'!G19*O24)/1000 -> 5185.565 | I24: =IF((J24>0),(J24-H24+E24),(I23-H24+E24)) -> 42692.042 | J24: =(K24+M24+L24) -> 0 | O24: =SUM(O23-N24) -> 94283 | R24: =Q24+R23 -> 0
A25: =A24+1 -> 13 | B25: =B24+1 -> 46116 | D25: =D24+E25 -> 77000 | G25: =G24-E25 -> 92425.45 | H25: =('Consumption Guide'!G20*O25)/1000 -> 5656.98 | I25: =IF((J25>0),(J25-H25+E25),(I24-H25+E25)) -> 37035.062 | J25: =(K25+M25+L25) -> 0 | O25: =SUM(O24-N25) -> 94283 | R25: =Q25+R24 -> 0
A26: =A25+1 -> 14 | B26: =B25+1 -> 46117 | D26: =D25+E26 -> 99000 | E26: 22000 | G26: =G25-E26 -> 70425.45 | H26: =('Consumption Guide'!G21*O26)/1000 -> 6128.395 | I26: =IF((J26>0),(J26-H26+E26),(I25-H26+E26)) -> 52906.667 | J26: =(K26+M26+L26) -> 0 | O26: =SUM(O25-N26) -> 94283 | R26: =Q26+R25 -> 0
A27: =A26+1 -> 15 | B27: =B26+1 -> 46118 | D27: =D26+E27 -> 99000 | G27: =G26-E27 -> 70425.45 | H27: =('Consumption Guide'!G22*O27)/1000 -> 6976.942 | I27: =IF((J27>0),(J27-H27+E27),(I26-H27+E27)) -> 45929.725 | J27: =(K27+M27+L27) -> 0 | O27: =SUM(O26-N27) -> 94283 | R27: =Q27+R26 -> 0
A28: =A27+1 -> 16 | B28: =B27+1 -> 46119 | D28: =D27+E28 -> 99000 | G28: =G27-E28 -> 70425.45 | H28: =('Consumption Guide'!G23*O28)/1000 -> 7071.225 | I28: =IF((J28>0),(J28-H28+E28),(I27-H28+E28)) -> 38858.5 | J28: =(K28+M28+L28) -> 0 | O28: =SUM(O27-N28) -> 94283 | R28: =Q28+R27 -> 0
A29: =A28+1 -> 17 | B29: =B28+1 -> 46120 | D29: =D28+E29 -> 99000 | G29: =G28-E29 -> 70425.45 | H29: =('Consumption Guide'!G24*O29)/1000 -> 7542.64 | I29: =IF((J29>0),(J29-H29+E29),(I28-H29+E29)) -> 31315.86 | J29: =(K29+M29+L29) -> 0 | O29: =SUM(O28-N29) -> 94283 | R29: =Q29+R28 -> 0
A30: =A29+1 -> 18 | B30: =B29+1 -> 46121 | D30: =D29+E30 -> 99000 | G30: =G29-E30 -> 70425.45 | H30: =('Consumption Guide'!G25*O30)/1000 -> 8202.621 | I30: =IF((J30>0),(J30-H30+E30),(I29-H30+E30)) -> 23113.239 | J30: =(K30+M30+L30) -> 0 | O30: =SUM(O29-N30) -> 94283 | R30: =Q30+R29 -> 0
A31: =A30+1 -> 19 | B31: =B30+1 -> 46122 | D31: =D30+E31 -> 99000 | G31: =G30-E31 -> 70425.45 | H31: =('Consumption Guide'!G26*O31)/1000 -> 8768.319 | I31: =IF((J31>0),(J31-H31+E31),(I30-H31+E31)) -> 14344.92 | J31: =(K31+M31+L31) -> 0 | O31: =SUM(O30-N31) -> 94283 | R31: =Q31+R30 -> 0
A32: =A31+1 -> 20 | B32: =B31+1 -> 46123 | D32: =D31+E32 -> 99000 | G32: =G31-E32 -> 70425.45 | H32: =('Consumption Guide'!G27*O32)/1000 -> 9145.451 | I32: =IF((J32>0),(J32-H32+E32),(I31-H32+E32)) -> 5199.469 | J32: =(K32+M32+L32) -> 0 | O32: =SUM(O31-N32) -> 94283 | R32: =Q32+R31 -> 0
A33: =A32+1 -> 21 | B33: =B32+1 -> 46124 | D33: =D32+E33 -> 99000 | G33: =G32-E33 -> 70425.45 | H33: =('Consumption Guide'!G28*O33)/1000 -> 9711.149 | I33: =IF((J33>0),(J33-H33+E33),(I32-H33+E33)) -> -4511.68 | J33: =(K33+M33+L33) -> 0 | O33: =SUM(O32-N33) -> 94283 | R33: =Q33+R32 -> 0
A34: =A33+1 -> 22 | B34: =B33+1 -> 46125 | D34: =D33+E34 -> 99000 | G34: =G33-E34 -> 70425.45 | H34: =('Consumption Guide'!G29*O34)/1000 -> 10088.281 | I34: =IF((J34>0),(J34-H34+E34),(I33-H34+E34)) -> -14599.961 | J34: =(K34+M34+L34) -> 0 | O34: =SUM(O33-N34) -> 94283 | R34: =Q34+R33 -> 0
A35: =A34+1 -> 23 | B35: =B34+1 -> 46126 | D35: =D34+E35 -> 99000 | G35: =G34-E35 -> 70425.45 | H35: =('Consumption Guide'!G30*O35)/1000 -> 10653.979 | I35: =IF((J35>0),(J35-H35+E35),(I34-H35+E35)) -> -25253.94 | J35: =(K35+M35+L35) -> 0 | O35: =SUM(O34-N35) -> 94283 | R35: =Q35+R34 -> 0
A36: =A35+1 -> 24 | B36: =B35+1 -> 46127 | D36: =D35+E36 -> 99000 | G36: =G35-E36 -> 70425.45 | H36: =('Consumption Guide'!G31*O36)/1000 -> 11125.394 | I36: =IF((J36>0),(J36-H36+E36),(I35-H36+E36)) -> -36379.334 | J36: =(K36+M36+L36) -> 0 | O36: =SUM(O35-N36) -> 94283 | R36: =Q36+R35 -> 0
A37: =A36+1 -> 25 | B37: =B36+1 -> 46128 | D37: =D36+E37 -> 99000 | G37: =H4-E36 -> 160281.1 | H37: =('Consumption Guide'!G32*O37)/1000 -> 11502.526 | I37: =IF((J37>0),(J37-H37+E37),(I36-H37+E37)) -> -47881.86 | J37: =(K37+M37+L37) -> 0 | O37: =SUM(O36-N37) -> 94283 | R37: =Q37+R36 -> 0
A38: =A37+1 -> 26 | B38: =B37+1 -> 46129 | D38: =D37+E38 -> 99000 | G38: =G37-E38 -> 160281.1 | H38: =('Consumption Guide'!G33*O38)/1000 -> 12068.224 | I38: =IF((J38>0),(J38-H38+E38),(I37-H38+E38)) -> -59950.084 | J38: =(K38+M38+L38) -> 0 | O38: =SUM(O37-N38) -> 94283 | R38: =Q38+R37 -> 0
A39: =A38+1 -> 27 | B39: =B38+1 -> 46130 | D39: =D38+E39 -> 99000 | G39: =G38-E39 -> 160281.1 | H39: =('Consumption Guide'!G34*O39)/1000 -> 12633.922 | I39: =IF((J39>0),(J39-H39+E39),(I38-H39+E39)) -> -72584.006 | J39: =(K39+M39+L39) -> 0 | O39: =SUM(O38-N39) -> 94283 | R39: =Q39+R38 -> 0
A40: =A39+1 -> 28 | B40: =B39+1 -> 46131 | D40: =D39+E40 -> 99000 | G40: =G39-E40 -> 160281.1 | H40: =('Consumption Guide'!G35*O40)/1000 -> 13105.337 | I40: =IF((J40>0),(J40-H40+E40),(I39-H40+E40)) -> -85689.343 | J40: =(K40+M40+L40) -> 0 | O40: =SUM(O39-N40) -> 94283 | R40: =Q40+R39 -> 0
A41: =A40+1 -> 29 | B41: =B40+1 -> 46132 | D41: =D40+E41 -> 99000 | G41: =G40-E41 -> 160281.1 | H41: =('Consumption Guide'!G36*O41)/1000 -> 13199.62 | I41: =IF((J41>0),(J41-H41+E41),(I40-H41+E41)) -> -98888.963 | J41: =(K41+M41+L41) -> 0 | O41: =SUM(O40-N41) -> 94283 | R41: =Q41+R40 -> 0
A42: =A41+1 -> 30 | B42: =B41+1 -> 46133 | D42: =D41+E42 -> 99000 | G42: =G41-E42 -> 160281.1 | H42: =('Consumption Guide'!G37*O42)/1000 -> 13388.186 | I42: =IF((J42>0),(J42-H42+E42),(I41-H42+E42)) -> -112277.15 | J42: =(K42+M42+L42) -> 0 | O42: =SUM(O41-N42) -> 94283 | R42: =Q42+R41 -> 0
...

Sheet SHED 9 & 10
A1: GROWER : | C1: DOUBLE B | E1: SHED | G1: 9 & 10
A2: NO. OF BIRDS | C2: 46105 | G2: STR ALL. | H2: =(C2*0.325) -> 14984.125 | I2: KG.
A3: PLACEMENT | C3: 46105 | G3: GWR ALL. | H3: =(C2*1.15) -> 53020.75 | I3: KG. | N3: SHED 9
B4: SHED 9 | C4: 46900 | G4: FIN ALL. | H4: =(C2*1.7) -> 78378.5 | I4: KG. | J4: WDW ALL C 10 | N4: SHED 10
B5: SHED 10 | C5: 46979 | G5: WDW ALL. | H5: =C2*1.5 -> 69157.5 | I5: KG.
R6: OVERALL | S6: % WGHT | U6: % WGHT
D7: TOTAL | Q7: FEED | R7: FEED | S7: MIXED | U7: MIXED
A8: AGE | B8: DAY | C8: DATE | D8: FEED | E8: FEED | G8: FEED | H8: FEED | I8: FEED | J8: SILO | K8: SILO | L8: SILO | M8: SILO | N8: CATCH | O8: BIRDS | P8: SHED | Q8: DIFF | R8: DISCREPANCY | S8: SHED 1 | T8: Weight(Kg) | U8: SHED 2 | V8: Weight(Kg)
C9: 43297 | D9: DEL. | E9: ORDERED | F9: SILO | G9: ALLOC. | H9: USAGE | I9: ON HAND | J9: TOTAL | K9: A | L9: B | M9: C | N9: MORTS | O9: LEFT | P9: # | W9: AGE
G12: =H2 -> 14984.125 | H12: 0 | I12: =IF((J12>0),(J12-H12+E12),(I11-H12+E12)) -> 0 | J12: =(K12+M12+L12) -> 0
A13: 1 | B13: =C3 -> 46105 | D13: =E13 -> 29000 | E13: 29000 | F13: a | G13: =G12-E13 -> -14015.875 | H13: =('Consumption Guide'!G8*O13)/1000 -> 1014.31 | I13: =IF((J13>0),(J13-H13+E13),(I12-H13+E13)) -> 27985.69 | J13: =(K13+M13+L13) -> 0 | O13: =SUM(C2-N13) -> 46105
A14: =A13+1 -> 2 | B14: =B13+1 -> 46106 | D14: =D13+E14 -> 41000 | E14: 12000 | G14: =G13-E14 -> -26015.875 | H14: =('Consumption Guide'!G9*O14)/1000 -> 1106.52 | I14: =IF((J14>0),(J14-H14+E14),(I13-H14+E14)) -> 44893.48 | J14: =(K14+M14+L14) -> 34000 | K14: 20000 | L14: 14000 | O14: =SUM(O13-N14) -> 46105 | R14: =Q14+R13 -> 0
A15: =A14+1 -> 3 | B15: =B14+1 -> 46107 | D15: =D14+E15 -> 41000 | G15: =G14-E15 -> -26015.875 | H15: =('Consumption Guide'!G10*O15)/1000 -> 1198.73 | I15: =IF((J15>0),(J15-H15+E15),(I14-H15+E15)) -> 22801.27 | J15: =(K15+M15+L15) -> 24000 | K15: 12000 | L15: 12000 | O15: =SUM(O14-N15) -> 46105 | R15: =Q15+R14 -> 0
A16: =A15+1 -> 4 | B16: =B15+1 -> 46108 | D16: =D15+E16 -> 41000 | G16: =G15-E16 -> -26015.875 | H16: =('Consumption Guide'!G11*O16)/1000 -> 1290.94 | I16: =IF((J16>0),(J16-H16+E16),(I15-H16+E16)) -> 34709.06 | J16: =(K16+M16+L16) -> 36000 | K16: 12000 | L16: 12000 | M16: 12000 | O16: =SUM(O15-N16) -> 46105 | R16: =Q16+R15 -> 0
A17: =A16+1 -> 5 | B17: =B16+1 -> 46109 | D17: =D16+E17 -> 41000 | G17: =G16-E17 -> -26015.875 | H17: =('Consumption Guide'!G12*O17)/1000 -> 1383.15 | I17: =IF((J17>0),(J17-H17+E17),(I16-H17+E17)) -> 33325.91 | J17: =(K17+M17+L17) -> 0 | O17: =SUM(O16-N17) -> 46105 | R17: =Q17+R16 -> 0
A18: =A17+1 -> 6 | B18: =B17+1 -> 46110 | D18: =D17+E18 -> 53000 | E18: 12000 | G18: =G17-E18 -> -38015.875 | H18: =('Consumption Guide'!G13*O18)/1000 -> 1475.36 | I18: =IF((J18>0),(J18-H18+E18),(I17-H18+E18)) -> 43850.55 | J18: =(K18+M18+L18) -> 0 | O18: =SUM(O17-N18) -> 46105 | R18: =Q18+R17 -> 0
A19: =A18+1 -> 7 | B19: =B18+1 -> 46111 | D19: =D18+E19 -> 53000 | G19: =G18-E19 -> -38015.875 | H19: =('Consumption Guide'!G14*O19)/1000 -> 1567.57 | I19: =IF((J19>0),(J19-H19+E19),(I18-H19+E19)) -> 30432.43 | J19: =(K19+M19+L19) -> 32000 | K19: 8000 | L19: 12000 | M19: 12000 | O19: =SUM(O18-N19) -> 46105 | R19: =Q19+R18 -> 0
A20: 8 | B20: =B19+1 -> 46112 | D20: =D19+E20 -> 53000 | G20: =G19-E20 -> -38015.875 | H20: =('Consumption Guide'!G15*O20)/1000 -> 1659.78 | I20: =IF((J20>0),(J20-H20+E20),(I19-H20+E20)) -> 28772.65 | J20: =(K20+M20+L20) -> 0 | O20: =SUM(O19-N20) -> 46105 | R20: =Q20+R19 -> 0
A21: =A20+1 -> 9 | B21: =B20+1 -> 46113 | D21: =D20+E21 -> 53000 | G21: =G20-E21 -> -38015.875 | H21: =('Consumption Guide'!G16*O21)/1000 -> 1844.2 | I21: =IF((J21>0),(J21-H21+E21),(I20-H21+E21)) -> 26928.45 | J21: =(K21+M21+L21) -> 0 | O21: =SUM(O20-N21) -> 46105 | R21: =Q21+R20 -> 0
A22: =A21+1 -> 10 | B22: =B21+1 -> 46114 | D22: =D21+E22 -> 65000 | E22: 12000 | G22: 96480 | H22: =('Consumption Guide'!G17*O22)/1000 -> 2074.725 | I22: =IF((J22>0),(J22-H22+E22),(I21-H22+E22)) -> 36853.725 | J22: =(K22+M22+L22) -> 0 | O22: =SUM(O21-N22) -> 46105 | R22: =Q22+R21 -> 0
A23: =A22+1 -> 11 | B23: =B22+1 -> 46115 | D23: =D22+E23 -> 65000 | G23: =H3-E23 -> 53020.75 | H23: =('Consumption Guide'!G18*O23)/1000 -> 2305.25 | I23: =IF((J23>0),(J23-H23+E23),(I22-H23+E23)) -> 34548.475 | J23: =(K23+M23+L23) -> 0 | O23: =SUM(O22-N23) -> 46105 | R23: =Q23+R22 -> 0
A24: =A23+1 -> 12 | B24: =B23+1 -> 46116 | D24: =D23+E24 -> 65000 | G24: =G23-E24 -> 53020.75 | H24: =('Consumption Guide'!G19*O24)/1000 -> 2535.775 | I24: =IF((J24>0),(J24-H24+E24),(I23-H24+E24)) -> 32012.7 | J24: =(K24+M24+L24) -> 0 | O24: =SUM(O23-N24) -> 46105 | R24: =Q24+R23 -> 0
A25: =A24+1 -> 13 | B25: =B24+1 -> 46117 | D25: =D24+E25 -> 87000 | E25: 22000 | G25: =G24-E25 -> 31020.75 | H25: =('Consumption Guide'!G20*O25)/1000 -> 2766.3 | I25: =IF((J25>0),(J25-H25+E25),(I24-H25+E25)) -> 51246.4 | J25: =(K25+M25+L25) -> 0 | O25: =SUM(O24-N25) -> 46105 | R25: =Q25+R24 -> 0
A26: =A25+1 -> 14 | B26: =B25+1 -> 46118 | D26: =D25+E26 -> 87000 | G26: =G25-E26 -> 31020.75 | H26: =('Consumption Guide'!G21*O26)/1000 -> 2996.825 | I26: =IF((J26>0),(J26-H26+E26),(I25-H26+E26)) -> 48249.575 | J26: =(K26+M26+L26) -> 0 | O26: =SUM(O25-N26) -> 46105 | R26: =Q26+R25 -> 0
A27: =A26+1 -> 15 | B27: =B26+1 -> 46119 | D27: =D26+E27 -> 87000 | G27: =G26-E27 -> 31020.75 | H27: =('Consumption Guide'!G22*O27)/1000 -> 3411.77 | I27: =IF((J27>0),(J27-H27+E27),(I26-H27+E27)) -> 44837.805 | J27: =(K27+M27+L27) -> 0 | O27: =SUM(O26-N27) -> 46105 | R27: =Q27+R26 -> 0
A28: =A27+1 -> 16 | B28: =B27+1 -> 46120 | D28: =D27+E28 -> 87000 | G28: =G27-E28 -> 31020.75 | H28: =('Consumption Guide'!G23*O28)/1000 -> 3457.875 | I28: =IF((J28>0),(J28-H28+E28),(I27-H28+E28)) -> 41379.93 | J28: =(K28+M28+L28) -> 0 | O28: =SUM(O27-N28) -> 46105 | R28: =Q28+R27 -> 0
A29: =A28+1 -> 17 | B29: =B28+1 -> 46121 | D29: =D28+E29 -> 87000 | G29: =G28-E29 -> 31020.75 | H29: =('Consumption Guide'!G24*O29)/1000 -> 3688.4 | I29: =IF((J29>0),(J29-H29+E29),(I28-H29+E29)) -> 37691.53 | J29: =(K29+M29+L29) -> 0 | O29: =SUM(O28-N29) -> 46105 | R29: =Q29+R28 -> 0
A30: =A29+1 -> 18 | B30: =B29+1 -> 46122 | D30: =D29+E30 -> 87000 | G30: =G29-E30 -> 31020.75 | H30: =('Consumption Guide'!G25*O30)/1000 -> 4011.135 | I30: =IF((J30>0),(J30-H30+E30),(I29-H30+E30)) -> 33680.395 | J30: =(K30+M30+L30) -> 0 | O30: =SUM(O29-N30) -> 46105 | R30: =Q30+R29 -> 0
A31: =A30+1 -> 19 | B31: =B30+1 -> 46123 | D31: =D30+E31 -> 87000 | G31: =G30-E31 -> 31020.75 | H31: =('Consumption Guide'!G26*O31)/1000 -> 4287.765 | I31: =IF((J31>0),(J31-H31+E31),(I30-H31+E31)) -> 29392.63 | J31: =(K31+M31+L31) -> 0 | O31: =SUM(O30-N31) -> 46105 | R31: =Q31+R30 -> 0
A32: =A31+1 -> 20 | B32: =B31+1 -> 46124 | D32: =D31+E32 -> 87000 | G32: =G31-E32 -> 31020.75 | H32: =('Consumption Guide'!G27*O32)/1000 -> 4472.185 | I32: =IF((J32>0),(J32-H32+E32),(I31-H32+E32)) -> 24920.445 | J32: =(K32+M32+L32) -> 0 | O32: =SUM(O31-N32) -> 46105 | R32: =Q32+R31 -> 0
A33: =A32+1 -> 21 | B33: =B32+1 -> 46125 | D33: =D32+E33 -> 87000 | G33: =G32-E33 -> 31020.75 | H33: =('Consumption Guide'!G28*O33)/1000 -> 4748.815 | I33: =IF((J33>0),(J33-H33+E33),(I32-H33+E33)) -> 20171.63 | J33: =(K33+M33+L33) -> 0 | O33: =SUM(O32-N33) -> 46105 | R33: =Q33+R32 -> 0
A34: =A33+1 -> 22 | B34: =B33+1 -> 46126 | D34: =D33+E34 -> 87000 | G34: =G33-E34 -> 31020.75 | H34: =('Consumption Guide'!G29*O34)/1000 -> 4933.235 | I34: =IF((J34>0),(J34-H34+E34),(I33-H34+E34)) -> 15238.395 | J34: =(K34+M34+L34) -> 0 | O34: =SUM(O33-N34) -> 46105 | R34: =Q34+R33 -> 0
A35: =A34+1 -> 23 | B35: =B34+1 -> 46127 | D35: =D34+E35 -> 87000 | G35: =G34-E35 -> 31020.75 | H35: =('Consumption Guide'!G30*O35)/1000 -> 5209.865 | I35: =IF((J35>0),(J35-H35+E35),(I34-H35+E35)) -> 10028.53 | J35: =(K35+M35+L35) -> 0 | O35: =SUM(O34-N35) -> 46105 | R35: =Q35+R34 -> 0
A36: =A35+1 -> 24 | B36: =B35+1 -> 46128 | D36: =D35+E36 -> 87000 | G36: =G35-E36 -> 31020.75 | H36: =('Consumption Guide'!G31*O36)/1000 -> 5440.39 | I36: =IF((J36>0),(J36-H36+E36),(I35-H36+E36)) -> 4588.14 | J36: =(K36+M36+L36) -> 0 | O36: =SUM(O35-N36) -> 46105 | R36: =Q36+R35 -> 0
A37: =A36+1 -> 25 | B37: =B36+1 -> 46129 | D37: =D36+E37 -> 87000 | G37: =H4-E36 -> 78378.5 | H37: =('Consumption Guide'!G32*O37)/1000 -> 5624.81 | I37: =IF((J37>0),(J37-H37+E37),(I36-H37+E37)) -> -1036.67 | J37: =(K37+M37+L37) -> 0 | O37: =SUM(O36-N37) -> 46105 | R37: =Q37+R36 -> 0
A38: =A37+1 -> 26 | B38: =B37+1 -> 46130 | D38: =D37+E38 -> 87000 | G38: =G37-E38 -> 78378.5 | H38: =('Consumption Guide'!G33*O38)/1000 -> 5901.44 | I38: =IF((J38>0),(J38-H38+E38),(I37-H38+E38)) -> -6938.11 | J38: =(K38+M38+L38) -> 0 | O38: =SUM(O37-N38) -> 46105 | R38: =Q38+R37 -> 0
A39: =A38+1 -> 27 | B39: =B38+1 -> 46131 | D39: =D38+E39 -> 87000 | G39: =G38-E39 -> 78378.5 | H39: =('Consumption Guide'!G34*O39)/1000 -> 6178.07 | I39: =IF((J39>0),(J39-H39+E39),(I38-H39+E39)) -> -13116.18 | J39: =(K39+M39+L39) -> 0 | O39: =SUM(O38-N39) -> 46105 | R39: =Q39+R38 -> 0
A40: =A39+1 -> 28 | B40: =B39+1 -> 46132 | D40: =D39+E40 -> 87000 | G40: =G39-E40 -> 78378.5 | H40: =('Consumption Guide'!G35*O40)/1000 -> 6408.595 | I40: =IF((J40>0),(J40-H40+E40),(I39-H40+E40)) -> -19524.775 | J40: =(K40+M40+L40) -> 0 | O40: =SUM(O39-N40) -> 46105 | R40: =Q40+R39 -> 0
A41: =A40+1 -> 29 | B41: =B40+1 -> 46133 | D41: =D40+E41 -> 87000 | G41: =G40-E41 -> 78378.5 | H41: =('Consumption Guide'!G36*O41)/1000 -> 6454.7 | I41: =IF((J41>0),(J41-H41+E41),(I40-H41+E41)) -> -25979.475 | J41: =(K41+M41+L41) -> 0 | O41: =SUM(O40-N41) -> 46105 | R41: =Q41+R40 -> 0
A42: =A41+1 -> 30 | B42: =B41+1 -> 46134 | D42: =D41+E42 -> 87000 | G42: =G41-E42 -> 78378.5 | H42: =('Consumption Guide'!G37*O42)/1000 -> 6546.91 | I42: =IF((J42>0),(J42-H42+E42),(I41-H42+E42)) -> -32526.385 | J42: =(K42+M42+L42) -> 0 | O42: =SUM(O41-N42) -> 46105 | R42: =Q42+R41 -> 0
...

Sheet SHED 11 & 12
A1: GROWER : | C1: DOUBLE B | E1: SHED | G1: 11 & 12
A2: NO. OF BIRDS | C2: =C4+C5+C6 -> 99000 | G2: STR ALL. | H2: =(C2*0.325) -> 32175 | I2: KG.
A3: PLACEMENT | C3: 46107 | G3: GWR ALL. | H3: =(C2*1.15) -> 113850 | I3: KG. | N3: SHED 11
B4: shed 11 | C4: 49500 | G4: FIN ALL. | H4: =(C2*1.7) -> 168300 | I4: KG. | J4: WDW ALL C 10 | N4: SHED 12
B5: shed 12 | C5: 49500 | G5: WDW ALL. | H5: =C2*1.5 -> 148500 | I5: KG.
R6: OVERALL | S6: % WGHT | U6: % WGHT
D7: TOTAL | Q7: FEED | R7: FEED | S7: MIXED | U7: MIXED
A8: AGE | B8: DAY | C8: DATE | D8: FEED | E8: FEED | G8: FEED | H8: FEED | I8: FEED | J8: SILO | K8: SILO | L8: SILO | M8: SILO | N8: CATCH | O8: BIRDS | P8: SHED | Q8: DIFF | R8: DISCREPANCY | S8: SHED 1 | T8: Weight(Kg) | U8: SHED 2 | V8: Weight(Kg)
C9: 43297 | D9: DEL. | E9: ORDERED | F9: SILO | G9: ALLOC. | H9: USAGE | I9: ON HAND | J9: TOTAL | K9: A | L9: B | M9: C | N9: MORTS | O9: LEFT | P9: # | W9: AGE
G12: =H2 -> 32175 | H12: 0 | I12: =IF((J12>0),(J12-H12+E12),(I11-H12+E12)) -> 0 | J12: =(K12+M12+L12) -> 0
A13: 1 | B13: =C3 -> 46107 | D13: =E13 -> 29000 | E13: 29000 | F13: a | G13: =G12-E13 -> 3175 | H13: =('Consumption Guide'!G8*O13)/1000 -> 2178 | I13: =IF((J13>0),(J13-H13+E13),(I12-H13+E13)) -> 62822 | J13: =(K13+M13+L13) -> 36000 | K13: 12000 | L13: 12000 | M13: 12000 | O13: =SUM(C2-N13) -> 99000
A14: =A13+1 -> 2 | B14: =B13+1 -> 46108 | D14: =D13+E14 -> 41000 | E14: 12000 | G14: =G13-E14 -> -8825 | H14: =('Consumption Guide'!G9*O14)/1000 -> 2376 | I14: =IF((J14>0),(J14-H14+E14),(I13-H14+E14)) -> 49624 | J14: =(K14+M14+L14) -> 40000 | K14: 12000 | L14: 16000 | M14: 12000 | O14: =SUM(O13-N14) -> 99000 | R14: =Q14+R13 -> 0
A15: =A14+1 -> 3 | B15: =B14+1 -> 46109 | D15: =D14+E15 -> 41000 | G15: =G14-E15 -> -8825 | H15: =('Consumption Guide'!G10*O15)/1000 -> 2574 | I15: =IF((J15>0),(J15-H15+E15),(I14-H15+E15)) -> 47050 | J15: =(K15+M15+L15) -> 0 | O15: =SUM(O14-N15) -> 99000 | R15: =Q15+R14 -> 0
A16: =A15+1 -> 4 | B16: =B15+1 -> 46110 | D16: =D15+E16 -> 53000 | E16: 12000 | G16: =G15-E16 -> -20825 | H16: =('Consumption Guide'!G11*O16)/1000 -> 2772 | I16: =IF((J16>0),(J16-H16+E16),(I15-H16+E16)) -> 56278 | J16: =(K16+M16+L16) -> 0 | O16: =SUM(O15-N16) -> 99000 | R16: =Q16+R15 -> 0
A17: =A16+1 -> 5 | B17: =B16+1 -> 46111 | D17: =D16+E17 -> 53000 | G17: =G16-E17 -> -20825 | H17: =('Consumption Guide'!G12*O17)/1000 -> 2970 | I17: =IF((J17>0),(J17-H17+E17),(I16-H17+E17)) -> 37030 | J17: =(K17+M17+L17) -> 40000 | K17: 12000 | L17: 16000 | M17: 12000 | O17: =SUM(O16-N17) -> 99000 | R17: =Q17+R16 -> 0
A18: =A17+1 -> 6 | B18: =B17+1 -> 46112 | D18: =D17+E18 -> 53000 | G18: =G17-E18 -> -20825 | H18: =('Consumption Guide'!G13*O18)/1000 -> 3168 | I18: =IF((J18>0),(J18-H18+E18),(I17-H18+E18)) -> 33862 | J18: =(K18+M18+L18) -> 0 | O18: =SUM(O17-N18) -> 99000 | R18: =Q18+R17 -> 0
A19: =A18+1 -> 7 | B19: =B18+1 -> 46113 | D19: =D18+E19 -> 53000 | G19: =G18-E19 -> -20825 | H19: =('Consumption Guide'!G14*O19)/1000 -> 3366 | I19: =IF((J19>0),(J19-H19+E19),(I18-H19+E19)) -> 30496 | J19: =(K19+M19+L19) -> 0 | O19: =SUM(O18-N19) -> 99000 | R19: =Q19+R18 -> 0
A20: 8 | B20: =B19+1 -> 46114 | D20: =D19+E20 -> 65000 | E20: 12000 | G20: =G19-E20 -> -32825 | H20: =('Consumption Guide'!G15*O20)/1000 -> 3564 | I20: =IF((J20>0),(J20-H20+E20),(I19-H20+E20)) -> 38932 | J20: =(K20+M20+L20) -> 0 | O20: =SUM(O19-N20) -> 99000 | R20: =Q20+R19 -> 0
A21: =A20+1 -> 9 | B21: =B20+1 -> 46115 | D21: =D20+E21 -> 65000 | G21: =G20-E21 -> -32825 | H21: =('Consumption Guide'!G16*O21)/1000 -> 3960 | I21: =IF((J21>0),(J21-H21+E21),(I20-H21+E21)) -> 34972 | J21: =(K21+M21+L21) -> 0 | O21: =SUM(O20-N21) -> 99000 | R21: =Q21+R20 -> 0
A22: =A21+1 -> 10 | B22: =B21+1 -> 46116 | D22: =D21+E22 -> 65000 | G22: 96480 | H22: =('Consumption Guide'!G17*O22)/1000 -> 4455 | I22: =IF((J22>0),(J22-H22+E22),(I21-H22+E22)) -> 30517 | J22: =(K22+M22+L22) -> 0 | O22: =SUM(O21-N22) -> 99000 | R22: =Q22+R21 -> 0
A23: =A22+1 -> 11 | B23: =B22+1 -> 46117 | D23: =D22+E23 -> 87000 | E23: 22000 | G23: =H3-E23 -> 91850 | H23: =('Consumption Guide'!G18*O23)/1000 -> 4950 | I23: =IF((J23>0),(J23-H23+E23),(I22-H23+E23)) -> 47567 | J23: =(K23+M23+L23) -> 0 | O23: =SUM(O22-N23) -> 99000 | R23: =Q23+R22 -> 0
A24: =A23+1 -> 12 | B24: =B23+1 -> 46118 | D24: =D23+E24 -> 87000 | G24: =G23-E24 -> 91850 | H24: =('Consumption Guide'!G19*O24)/1000 -> 5445 | I24: =IF((J24>0),(J24-H24+E24),(I23-H24+E24)) -> 42122 | J24: =(K24+M24+L24) -> 0 | O24: =SUM(O23-N24) -> 99000 | R24: =Q24+R23 -> 0
A25: =A24+1 -> 13 | B25: =B24+1 -> 46119 | D25: =D24+E25 -> 87000 | G25: =G24-E25 -> 91850 | H25: =('Consumption Guide'!G20*O25)/1000 -> 5940 | I25: =IF((J25>0),(J25-H25+E25),(I24-H25+E25)) -> 36182 | J25: =(K25+M25+L25) -> 0 | O25: =SUM(O24-N25) -> 99000 | R25: =Q25+R24 -> 0
A26: =A25+1 -> 14 | B26: =B25+1 -> 46120 | D26: =D25+E26 -> 87000 | G26: =G25-E26 -> 91850 | H26: =('Consumption Guide'!G21*O26)/1000 -> 6435 | I26: =IF((J26>0),(J26-H26+E26),(I25-H26+E26)) -> 29747 | J26: =(K26+M26+L26) -> 0 | O26: =SUM(O25-N26) -> 99000 | R26: =Q26+R25 -> 0
A27: =A26+1 -> 15 | B27: =B26+1 -> 46121 | D27: =D26+E27 -> 87000 | G27: 50000 | H27: =('Consumption Guide'!G22*O27)/1000 -> 7326 | I27: =IF((J27>0),(J27-H27+E27),(I26-H27+E27)) -> 22421 | J27: =(K27+M27+L27) -> 0 | O27: =SUM(O26-N27) -> 99000 | R27: =Q27+R26 -> 0
A28: =A27+1 -> 16 | B28: =B27+1 -> 46122 | D28: =D27+E28 -> 87000 | G28: =G27-E28 -> 50000 | H28: =('Consumption Guide'!G23*O28)/1000 -> 7425 | I28: =IF((J28>0),(J28-H28+E28),(I27-H28+E28)) -> 14996 | J28: =(K28+M28+L28) -> 0 | O28: =SUM(O27-N28) -> 99000 | R28: =Q28+R27 -> 0
A29: =A28+1 -> 17 | B29: =B28+1 -> 46123 | D29: =D28+E29 -> 87000 | G29: =G28-E29 -> 50000 | H29: =('Consumption Guide'!G24*O29)/1000 -> 7920 | I29: =IF((J29>0),(J29-H29+E29),(I28-H29+E29)) -> 7076 | J29: =(K29+M29+L29) -> 0 | O29: =SUM(O28-N29) -> 99000 | R29: =Q29+R28 -> 0
A30: =A29+1 -> 18 | B30: =B29+1 -> 46124 | D30: =D29+E30 -> 87000 | G30: =G29-E30 -> 50000 | H30: =('Consumption Guide'!G25*O30)/1000 -> 8613 | I30: =IF((J30>0),(J30-H30+E30),(I29-H30+E30)) -> -1537 | J30: =(K30+M30+L30) -> 0 | O30: =SUM(O29-N30) -> 99000 | R30: =Q30+R29 -> 0
A31: =A30+1 -> 19 | B31: =B30+1 -> 46125 | D31: =D30+E31 -> 87000 | G31: =G30-E31 -> 50000 | H31: =('Consumption Guide'!G26*O31)/1000 -> 9207 | I31: =IF((J31>0),(J31-H31+E31),(I30-H31+E31)) -> -10744 | J31: =(K31+M31+L31) -> 0 | O31: =SUM(O30-N31) -> 99000 | R31: =Q31+R30 -> 0
A32: =A31+1 -> 20 | B32: =B31+1 -> 46126 | D32: =D31+E32 -> 87000 | G32: =G31-E32 -> 50000 | H32: =('Consumption Guide'!G27*O32)/1000 -> 9603 | I32: =IF((J32>0),(J32-H32+E32),(I31-H32+E32)) -> -20347 | J32: =(K32+M32+L32) -> 0 | O32: =SUM(O31-N32) -> 99000 | R32: =Q32+R31 -> 0
A33: =A32+1 -> 21 | B33: =B32+1 -> 46127 | D33: =D32+E33 -> 87000 | G33: =G32-E33 -> 50000 | H33: =('Consumption Guide'!G28*O33)/1000 -> 10197 | I33: =IF((J33>0),(J33-H33+E33),(I32-H33+E33)) -> -30544 | J33: =(K33+M33+L33) -> 0 | O33: =SUM(O32-N33) -> 99000 | R33: =Q33+R32 -> 0
A34: =A33+1 -> 22 | B34: =B33+1 -> 46128 | D34: =D33+E34 -> 87000 | G34: =G33-E34 -> 50000 | H34: =('Consumption Guide'!G29*O34)/1000 -> 10593 | I34: =IF((J34>0),(J34-H34+E34),(I33-H34+E34)) -> -41137 | J34: =(K34+M34+L34) -> 0 | O34: =SUM(O33-N34) -> 99000 | R34: =Q34+R33 -> 0
A35: =A34+1 -> 23 | B35: =B34+1 -> 46129 | D35: =D34+E35 -> 87000 | G35: =G34-E35 -> 50000 | H35: =('Consumption Guide'!G30*O35)/1000 -> 11187 | I35: =IF((J35>0),(J35-H35+E35),(I34-H35+E35)) -> -52324 | J35: =(K35+M35+L35) -> 0 | O35: =SUM(O34-N35) -> 99000 | R35: =Q35+R34 -> 0
